Workbook

Sheet Start Here
B2: GAIA 2.0 — Green AI Assessment Tool
B3: Version 2.2.0 · 2026-09-16 · MIT License · Generated by build_workbook.py from data/*.csv — never hand-edited (FRAMEWORK.md §9)
B6: What this tool is
B7: GAIA answers three questions for an organization that USES AI (via APIs, hosted deployments, or self-hosted models): (1) how large is the environmental footprint of a use case — energy, carbon, and water — with uncertainty bounds and data provenance; (2) is that footprint reasonable for the task, graded against published measurements; (3) what should change, ranked by evidence. Method: Ground → Assess → Interpret → Act.
B9: How to use it — 5 steps
B10: 1. Open the Assessment sheet and pick your Model and Task class from the dropdowns.
B11: 2. Enter your token profile (tokens in / out per request) and queries per month — class defaults are shown next to the inputs for reference.
B12: 3. Choose the Facility profile and Hosting region (keep the honest defaults — 'Unknown (API default)' and 'Global average' — if you don't know).
B13: 4. Answer the three frugality questions (necessity, right-sizing, token discipline) with Yes/No.
B14: 5. Read the Results block: low/central/high energy, carbon (dual), and water; the efficiency grade and frugality flag; and the guidance line. Then pick levers on the Mitigation sheet. Track months on the Usage Log.
B16: Color key
B17: Input cell — light yellow: the cells you edit (dropdowns or typed values)
... B27: The Tier column is the provenance of the number, not the quality of the model. Most rows are T4 (modelled): no closed provider publishes per-model serving energy, and a user of a closed API cannot measure it. Rows marked with a class anchor in their Basis share one placeholder value across every closed model of that capability class — that is a statement about missing disclosure, not a finding that the models are equally efficient. Open-weight rows are the ones you can meter yourself, which moves them to T1 and cuts the uncertainty band roughly fourfold.

Sheet Assessment
B1: GAIA 2.0 — AI Use-Case Assessment
B2: Edit the yellow cells only. Blue cells are computed from the Engine sheet. All results are low / central / high (P2).
B3: INPUTS
B4: 1 · Model | C4: GPT-4o | D4: Dropdown — full provenance in 'Model Database'
B5: 2 · Task class | C5: Standard | D5: L / S / H / R — definitions and bands in 'Grading'
B6: 3 · Tokens in (per request) | C6: 500 | D6: =IFERROR("Class default: "&INDEX(Grading!$C$2:$C$5,MATCH($C$5,Grading!$A$2:$A$5,0)),"")
B7: 4 · Tokens out (per request) | C7: 300 | D7: =IFERROR("Class default: "&INDEX(Grading!$D$2:$D$5,MATCH($C$5,Grading!$A$2:$A$5,0)),"")
B8: 5 · Queries per month | C8: 1000
B9: 6 · Facility profile | C9: Unknown (API default) | D9: PUE and WUE per profile in 'Facility Profiles'
B10: 7 · Hosting region | C10: Global average | D10: Grid CI and EWIF in 'Region Factors'; keep 'Global average' if unknown
B11: 8 · Embodied adder | C11: 0.25 | D11: Default 0.25 of location-based carbon; sensible range 0.10–0.50 (§4.6)
B12: 9 · Market-based CI (g CO2e/kWh) — optional | D12: Leave blank unless your provider discloses a market-based factor; reported beside, never instead of, location-based (P6)
B13: 10 · Cached input share (0–1) — optional | C13: 0 | D13: Share of input tokens served from a prompt cache. Cache hits skip prefill, so those tokens carry no energy. Output tokens are never cached (§4.1).
B14: FRUGALITY CHECK (§5.3) — three auditable Yes/No questions
B15: Q1 · Necessity — does the task need generative AI at all (vs. search, template, rules, or a human)? | C15: Yes
B16: Q2 · Right-sizing — has a model ≥1 capability class smaller been evaluated on this task, with documented quality results? | C16: Yes
B17: Q3 · Token discipline — are prompts, retrieval payloads and reasoning budgets bounded (max-token / thinking caps, caching)? | C17: Yes
B19: RESULTS — computed on the Engine sheet; do not edit
B20: Metric | C20: Low | D20: Central | E20: High | F20: Unit / note
B21: Energy per request | C21: =Engine!$B$48 | D21: =Engine!$B$39 | E21: =Engine!$B$49 | F21: Wh / request (full-stack: IT × PUE)
B22: Energy per month | C22: =Engine!$B$50 | D22: =Engine!$B$41 | E22: =Engine!$B$51 | F22: kWh / month
B23: Carbon — location-based | C23: =Engine!$B$52 | D23: =Engine!$B$42 | E23: =Engine!$B$53 | F23: kg CO2e / month (physical grid mix)
B24: Carbon — market-based | C24: =Engine!$B$58 | D24: =Engine!$B$43 | E24: =Engine!$B$59 | F24: kg CO2e / month — 'not provided' unless input 9 is set (P6)
B25: Embodied carbon | C25: =Engine!$B$54 | D25: =Engine!$B$44 | E25: =Engine!$B$55 | F25: kg CO2e / month = location-based × adder (§4.6)
B26: Water (on-site + off-site) | C26: =Engine!$B$56 | D26: =Engine!$B$45 | E26: =Engine!$B$57 | F26: L / month (two-path model, §4.4)
B28: EFFICIENCY GRADE — central Wh/request vs task-class bands (§5.2) | C28: =Engine!$B$62 | E28: Frugality flag | F28: =Engine!$B$64
E29: Model data tier | F29: =Engine!$B$23
B31: GUIDANCE (§5.4 — grade × flag) | C31: =Engine!$B$65
B33: REAL-WORLD EQUIVALENTS — communication aids, not results (sourced factors on Engine sheet)
B34: ≈ Hours of a 10 W LED bulb | C34: =Engine!$B$74 | D34: hours / month
B35: ≈ Smartphone full charges | C35: =Engine!$B$75 | D35: charges / month
B36: ≈ Km driven in an average petrol car | C36: =Engine!$B$76 | D36: km / month
B37: ≈ 8-minute showers | C37: =Engine!$B$79 | D37: showers / month

Sheet Engine
A1: GAIA 2.0 Engine — every intermediate calculation, documented
A2: All Assessment results reference this sheet. Column D documents each formula in framework notation (FRAMEWORK.md §4–§5). Generated — do not edit.
A4: 1 · INPUTS (echoed from the Assessment sheet)
A5: Model | B5: =IF(Assessment!$C$4="","",Assessment!$C$4) | D5: Assessment input 1
A6: Task class | B6: =IF(Assessment!$C$5="","",Assessment!$C$5) | D6: Assessment input 2
A7: Tokens in per request (T_in) | B7: =Assessment!$C$6 | C7: tokens | D7: Assessment input 3
A8: Tokens out per request (T_out) | B8: =Assessment!$C$7 | C8: tokens | D8: Assessment input 4
A9: Queries per month (Q_month) | B9: =Assessment!$C$8 | C9: requests | D9: Assessment input 5
A10: Facility profile | B10: =IF(Assessment!$C$9="","",Assessment!$C$9) | D10: Assessment input 6
A11: Hosting region | B11: =IF(Assessment!$C$10="","",Assessment!$C$10) | D11: Assessment input 7
A12: Embodied adder | B12: =Assessment!$C$11 | C12: fraction | D12: Assessment input 8 (default 0.25; range 0.10–0.50, §4.6)
A13: Market-based CI (optional) | B13: =IF(Assessment!$C$12="","",Assessment!$C$12) | C13: g CO2e/kWh | D13: Assessment input 9; blank = not provided (P6)
A14: Cached input share | B14: =IF(Assessment!$C$13="",0,Assessment!$C$13) | C14: fraction 0–1 | D14: Assessment input 10; share of input tokens served from a prompt cache. Cache hits skip prefill recomputation, so those tokens carry no generation energy. Output tokens are never cached (§4.1).
A15: Frugality Q1 — necessity | B15: =IF(Assessment!$C$15="","",Assessment!$C$15) | D15: Yes/No
A16: Frugality Q2 — right-sizing | B16: =IF(Assessment!$C$16="","",Assessment!$C$16) | D16: Yes/No
A17: Frugality Q3 — token discipline | B17: =IF(Assessment!$C$17="","",Assessment!$C$17) | D17: Yes/No
A19: 2 · LOOKED-UP FACTORS (INDEX/MATCH against the data sheets)
A20: e_out — model energy, central | B20: =IFERROR(INDEX('Model Database'!$L$2:$L$136,MATCH($B$5,'Model Database'!$A$2:$A$136,0)),"") | C20: Wh / 1k output tokens | D20: models.csv wh_per_1k_output_tokens_it — IT boundary (accelerator + host); serving-stack multiplier S already included
A21: e_out low bound | B21: =IFERROR(INDEX('Model Database'!$M$2:$M$136,MATCH($B$5,'Model Database'!$A$2:$A$136,0)),"") | C21: Wh / 1k output tokens | D21: models.csv wh_low (tier band = default minimum width; some rows are wider with justification in their basis column)
A22: e_out high bound | B22: =IFERROR(INDEX('Model Database'!$N$2:$N$136,MATCH($B$5,'Model Database'!$A$2:$A$136,0)),"") | C22: Wh / 1k output tokens | D22: models.csv wh_high (tier band = default minimum width; some rows are wider with justification in their basis column)
A23: Data-quality tier of model row | B23: =IFERROR(INDEX('Model Database'!$O$2:$O$136,MATCH($B$5,'Model Database'!$A$2:$A$136,0)),"") | D23: T1 measured / T2 disclosed / T3 benchmarked / T4 modeled (§4.5)
A24: Low scale factor | B24: =IFERROR($B$21/$B$20,"") | C24: × | D24: wh_low / e_out — every output is scaled by this for the low bound
A25: High scale factor | B25: =IFERROR($B$22/$B$20,"") | C25: × | D25: wh_high / e_out — every output is scaled by this for the high bound
A26: PUE — facility overhead | B26: =IFERROR(INDEX('Facility Profiles'!$B$2:$B$6,MATCH($B$10,'Facility Profiles'!$A$2:$A$6,0)),"") | C26: × | D26: facilities.csv pue for the chosen profile
A27: WUE — on-site water | B27: =IFERROR(INDEX('Facility Profiles'!$E$2:$E$6,MATCH($B$10,'Facility Profiles'!$A$2:$A$6,0)),"") | C27: L/kWh (IT energy) | D27: facilities.csv wue_l_kwh for the chosen profile
A28: CI — location-based grid carbon | B28: =IFERROR(INDEX('Region Factors'!$B$2:$B$21,MATCH($B$11,'Region Factors'!$A$2:$A$21,0)),"") | C28: g CO2e/kWh | D28: regions.csv ci_location_gco2_kwh for the chosen region
A29: EWIF — off-site water | B29: =IFERROR(INDEX('Region Factors'!$E$2:$E$21,MATCH($B$11,'Region Factors'!$A$2:$A$21,0)),"") | C29: L/kWh (total energy) | D29: regions.csv ewif_l_kwh for the chosen region
A30: Task-class default tokens in | B30: =IFERROR(INDEX(Grading!$C$2:$C$5,MATCH($B$6,Grading!$A$2:$A$5,0)),"") | C30: tokens | D30: grading.csv tokens_in_default — reference for Assessment input 3
A31: Task-class default tokens out | B31: =IFERROR(INDEX(Grading!$D$2:$D$5,MATCH($B$6,Grading!$A$2:$A$5,0)),"") | C31: tokens | D31: grading.csv tokens_out_default — reference for Assessment input 4
A32: Grade A maximum | B32: =IFERROR(INDEX(Grading!$E$2:$E$5,MATCH($B$6,Grading!$A$2:$A$5,0)),"") | C32: Wh/request | D32: grading.csv grade_a_max_wh for the chosen task class
A33: Grade B maximum | B33: =IFERROR(INDEX(Grading!$F$2:$F$5,MATCH($B$6,Grading!$A$2:$A$5,0)),"") | C33: Wh/request | D33: grading.csv grade_b_max_wh
A34: Grade C maximum | B34: =IFERROR(INDEX(Grading!$G$2:$G$5,MATCH($B$6,Grading!$A$2:$A$5,0)),"") | C34: Wh/request | D34: grading.csv grade_c_max_wh
A35: Grade D maximum | B35: =IFERROR(INDEX(Grading!$H$2:$H$5,MATCH($B$6,Grading!$A$2:$A$5,0)),"") | C35: Wh/request | D35: grading.csv grade_d_max_wh; above this = grade E
A37: 3 · CENTRAL ESTIMATE (§4 equations)
A38: E_IT_request — IT energy per request | B38: =IFERROR($B$20*($B$8+$B$7*(1-$B$14)/10)/1000,"") | C38: Wh | D38: E_IT = e_out × (T_out + T_in × (1 − c) / 10) / 1000 — input tokens cost ≈1/10 of output tokens (§4.1, k=10); c is the cached input share, whose tokens skip prefill entirely
A39: E_request — full energy per request | B39: =IFERROR($B$38*$B$26,"") | C39: Wh | D39: E_request = E_IT_request × PUE (§4.1; S is already inside e_out)
A40: E_IT_month — monthly IT energy | B40: =IFERROR($B$38*$B$9/1000,"") | C40: kWh | D40: E_IT_month = E_IT_request × Q_month / 1000
A41: E_month — monthly total energy | B41: =IFERROR($B$39*$B$9/1000,"") | C41: kWh | D41: E_month = E_request × Q_month / 1000 (§4.2)
A42: Carbon, location-based | B42: =IFERROR($B$41*$B$28/1000,"") | C42: kg CO2e/month | D42: C_op(location) = E_month × CI_location / 1000 (§4.3)
A43: Carbon, market-based | B43: =IF(OR($B$13="",NOT(ISNUMBER($B$13))),"not provided",IFERROR($B$41*$B$13/1000,"")) | C43: kg CO2e/month | D43: C_op(market) = E_month × CI_market / 1000 — ONLY if a numeric market CI is supplied; never blended with location-based (P6)
...

Sheet Model Database
A1: Model | B1: Provider | C1: Weights | D1: Licence | E1: Capability class | F1: Architecture | G1: Total params (B) | H1: Active params (B) | I1: Context | J1: Released | K1: Reasoning mode | L1: Wh per 1k output tokens (central, IT boundary) | M1: Low | N1: High | O1: Tier | P1: Vintage | Q1: Basis | R1: Source | S1: Status
A2: GPT-6 Astra | B2: OpenAI | C2: Proprietary | D2: proprietary | E2: Frontier | F2: undisclosed | I2: 1.05M | J2: 2026-09-03 | K2: always | L2: 1.2 | M2: 0.39 | N2: 3.6 | O2: T4 | P2: 2026-09-03 | Q2: Class anchor for frontier closed-weight serving (§4.5): no parameter disclosure and no published per-request measurement, so the row carries the full T4 band. The ceiling for an API row is T2 and only the provider can lift it (§4.8). Reasoning cannot be disabled — every call incurs reasoning tokens, so use the Reasoning task class, whose token profile accounts for hidden thinking. | R2: OpenAI model documentation and release notes (developers.openai.com, openai.com), Sept 2026 | S2: current
A3: GPT-5.6 Sol | B3: OpenAI | C3: Proprietary | D3: proprietary | E3: Frontier | F3: undisclosed | I3: 1.05M | J3: 2026-07-09 | K3: optional | L3: 1.2 | M3: 0.39 | N3: 3.6 | O3: T4 | P3: 2026-07-09 | Q3: Class anchor for frontier closed-weight serving (§4.5): no parameter disclosure and no published per-request measurement, so the row carries the full T4 band. The ceiling for an API row is T2 and only the provider can lift it (§4.8). | R3: OpenAI model documentation and release notes (developers.openai.com, openai.com), Sept 2026 | S3: current
A4: GPT-5.6 Terra | B4: OpenAI | C4: Proprietary | D4: proprietary | E4: Mid | F4: undisclosed | I4: 1.05M | J4: 2026-07-09 | K4: optional | L4: 0.3 | M4: 0.09 | N4: 0.9 | O4: T4 | P4: 2026-07-09 | Q4: Class anchor for mid closed-weight serving (§4.5): no parameter disclosure and no published per-request measurement, so the row carries the full T4 band. The ceiling for an API row is T2 and only the provider can lift it (§4.8). | R4: OpenAI model documentation and release notes (developers.openai.com, openai.com), Sept 2026 | S4: current
A5: GPT-5.6 Luna | B5: OpenAI | C5: Proprietary | D5: proprietary | E5: Small | F5: undisclosed | I5: 1.05M | J5: 2026-07-09 | K5: optional | L5: 0.12 | M5: 0.04 | N5: 0.36 | O5: T4 | P5: 2026-07-09 | Q5: Class anchor for small closed-weight serving (§4.5): no parameter disclosure and no published per-request measurement, so the row carries the full T4 band. The ceiling for an API row is T2 and only the provider can lift it (§4.8). | R5: OpenAI model documentation and release notes (developers.openai.com, openai.com), Sept 2026 | S5: current
A6: GPT-5.5 | B6: OpenAI | C6: Proprietary | D6: proprietary | E6: Frontier | F6: undisclosed | I6: 1.05M | J6: 2026-04-23 | K6: optional | L6: 1.2 | M6: 0.39 | N6: 3.6 | O6: T4 | P6: 2026-04-23 | Q6: Class anchor for frontier closed-weight serving (§4.5): no parameter disclosure and no published per-request measurement, so the row carries the full T4 band. The ceiling for an API row is T2 and only the provider can lift it (§4.8). | R6: OpenAI model documentation and release notes (developers.openai.com, openai.com), Sept 2026 | S6: current
A7: GPT-5.5 Pro | B7: OpenAI | C7: Proprietary | D7: proprietary | E7: Frontier | F7: undisclosed | I7: 1.05M | J7: 2026-04-24 | K7: always | L7: 1.2 | M7: 0.39 | N7: 3.6 | O7: T4 | P7: 2026-04-24 | Q7: Class anchor for frontier closed-weight serving (§4.5): no parameter disclosure and no published per-request measurement, so the row carries the full T4 band. The ceiling for an API row is T2 and only the provider can lift it (§4.8). | R7: OpenAI model documentation and release notes (developers.openai.com, openai.com), Sept 2026 | S7: current
A8: GPT-5.4 | B8: OpenAI | C8: Proprietary | D8: proprietary | E8: Frontier | F8: undisclosed | I8: 400K | J8: 2026-03-05 | K8: optional | L8: 1.2 | M8: 0.39 | N8: 3.6 | O8: T4 | P8: 2026-03-05 | Q8: Class anchor for frontier closed-weight serving (§4.5): no parameter disclosure and no published per-request measurement, so the row carries the full T4 band. The ceiling for an API row is T2 and only the provider can lift it (§4.8). | R8: OpenAI model documentation and release notes (developers.openai.com, openai.com), Sept 2026 | S8: current
A9: GPT-5.4 mini | B9: OpenAI | C9: Proprietary | D9: proprietary | E9: Mid | F9: undisclosed | I9: 400K | J9: 2026-03-17 | K9: optional | L9: 0.3 | M9: 0.09 | N9: 0.9 | O9: T4 | P9: 2026-03-17 | Q9: Class anchor for mid closed-weight serving (§4.5): no parameter disclosure and no published per-request measurement, so the row carries the full T4 band. The ceiling for an API row is T2 and only the provider can lift it (§4.8). | R9: OpenAI model documentation and release notes (developers.openai.com, openai.com), Sept 2026 | S9: current
A10: GPT-5.4 nano | B10: OpenAI | C10: Proprietary | D10: proprietary | E10: Small | F10: undisclosed | I10: 400K | J10: 2026-03-17 | K10: optional | L10: 0.12 | M10: 0.04 | N10: 0.36 | O10: T4 | P10: 2026-03-17 | Q10: Class anchor for small closed-weight serving (§4.5): no parameter disclosure and no published per-request measurement, so the row carries the full T4 band. The ceiling for an API row is T2 and only the provider can lift it (§4.8). | R10: OpenAI model documentation and release notes (developers.openai.com, openai.com), Sept 2026 | S10: current
A11: GPT-5.3-Codex | B11: OpenAI | C11: Proprietary | D11: proprietary | E11: Frontier | F11: undisclosed | I11: 400K | J11: 2026-02-05 | K11: optional | L11: 1.2 | M11: 0.39 | N11: 3.6 | O11: T4 | P11: 2026-02-05 | Q11: Class anchor for frontier closed-weight serving (§4.5): no parameter disclosure and no published per-request measurement, so the row carries the full T4 band. The ceiling for an API row is T2 and only the provider can lift it (§4.8). | R11: OpenAI model documentation and release notes (developers.openai.com, openai.com), Sept 2026 | S11: current
A12: GPT-5.2 | B12: OpenAI | C12: Proprietary | D12: proprietary | E12: Frontier | F12: undisclosed | I12: 400K | J12: 2025-12-11 | K12: optional | L12: 1.2 | M12: 0.39 | N12: 3.6 | O12: T4 | P12: 2025-12-11 | Q12: Class anchor for frontier closed-weight serving (§4.5): no parameter disclosure and no published per-request measurement, so the row carries the full T4 band. The ceiling for an API row is T2 and only the provider can lift it (§4.8). | R12: OpenAI model documentation and release notes (developers.openai.com, openai.com), Sept 2026 | S12: current
A13: o3-deep-research | B13: OpenAI | C13: Proprietary | D13: proprietary | E13: Frontier | F13: undisclosed | I13: 200K | J13: 2025-10-10 | K13: always | L13: 1.2 | M13: 0.39 | N13: 3.6 | O13: T4 | P13: 2025-10-10 | Q13: Class anchor for frontier closed-weight serving (§4.5): no parameter disclosure and no published per-request measurement, so the row carries the full T4 band. The ceiling for an API row is T2 and only the provider can lift it (§4.8). Deep-research runs emit very large hidden reasoning traces; grade on the Reasoning class and measure your own token usage before trusting the default. | R13: OpenAI model documentation and release notes (developers.openai.com, openai.com), Sept 2026 | S13: current
A14: ChatGPT (fleet average) | B14: OpenAI | C14: Proprietary | D14: proprietary | E14: Frontier | F14: undisclosed | I14: — | J14: 2025-06 | K14: mixed | L14: 1 | M14: 0.5 | N14: 2 | O14: T2 | P14: 2025-06 | Q14: Provider-disclosed 0.34 Wh per average query, boundary unstated; converted at an assumed ~300 output tokens per average query. A fleet average is dominated by small models and short answers — it is not the rate of any one model, least of all a frontier one. | R14: OpenAI per-query energy statement (June 2025); conversion per FRAMEWORK.md §4.5 | S14: current
A15: gpt-oss-120b | B15: OpenAI | C15: Open | D15: Apache-2.0 | E15: Mid | F15: MoE | G15: 117 | H15: 5.1 | I15: 131K | J15: 2025-08-05 | K15: optional | L15: 0.011 | M15: 0.0036 | N15: 0.033 | O15: T4 | P15: 2025-08-05 | Q15: T4-physics(A=5.1): e_out = 2*N_active/(eta*u*3600)*S with eta=1.4e12 FLOPs/J (H100-class BF16), u=0.3, S=1.7. Open weights, so this row can be moved to T1 by metering your own deployment (§4.8). | R15: OpenAI gpt-oss model card (Aug 2025) | S15: current
A16: gpt-oss-20b | B16: OpenAI | C16: Open | D16: Apache-2.0 | E16: Small | F16: MoE | G16: 21 | H16: 3.6 | I16: 131K | J16: 2025-08-05 | K16: optional | L16: 0.0081 | M16: 0.0026 | N16: 0.025 | O16: T4 | P16: 2025-08-05 | Q16: T4-physics(A=3.6): e_out = 2*N_active/(eta*u*3600)*S with eta=1.4e12 FLOPs/J (H100-class BF16), u=0.3, S=1.7. Open weights, so this row can be moved to T1 by metering your own deployment (§4.8). | R16: OpenAI gpt-oss model card (Aug 2025) | S16: current
A17: GPT-4o | B17: OpenAI | C17: Proprietary | D17: proprietary | E17: Frontier | F17: undisclosed | I17: 128K | J17: 2024-05-13 | K17: no | L17: 0.8 | M17: 0.3 | N17: 2.4 | O17: T3 | P17: 2025-05 | Q17: Jegham et al. measured ~1.2 Wh per medium query; Epoch AI's first-principles estimate is ~0.3 Wh for a typical ~500-token answer. The central value reconciles both; the band is wider than T3 requires because the two disagree. | R17: arXiv:2505.09598; Epoch AI, 'How much energy does ChatGPT use?' (2025) | S17: legacy
A18: GPT-4o mini | B18: OpenAI | C18: Proprietary | D18: proprietary | E18: Small | F18: undisclosed | I18: 128K | J18: 2024-07 | K18: no | L18: 0.3 | M18: 0.1 | N18: 0.9 | O18: T3 | P18: 2025-05 | Q18: Jegham et al. ~1.4 Wh per medium query — higher than parameter physics implies, a batching penalty small models pay in shared serving. Bounds widened for that conflict. | R18: arXiv:2505.09598 | S18: legacy
A19: GPT-4.1 nano | B19: OpenAI | C19: Proprietary | D19: proprietary | E19: Small | F19: undisclosed | I19: 1M | J19: 2025-04 | K19: no | L19: 0.08 | M19: 0.03 | N19: 0.24 | O19: T3 | P19: 2025-05 | Q19: Lowest-energy commercial model in the Jegham et al. benchmark — more than 70x below o3 on the same prompts. This spread is the empirical basis of mitigation lever 1. | R19: arXiv:2505.09598 | S19: legacy
A20: o3 | B20: OpenAI | C20: Proprietary | D20: proprietary | E20: Frontier | F20: undisclosed | I20: 200K | J20: 2025-04-16 | K20: always | L20: 5 | M20: 2.5 | N20: 10 | O20: T3 | P20: 2025-05 | Q20: Jegham et al.: 21.4 Wh per medium prompt and over 33 Wh per long prompt including hidden reasoning tokens; expressed here as an effective rate per 1k generated tokens. Anchors the grade-E band for the reasoning class. | R20: arXiv:2505.09598 | S20: legacy
A21: GPT-5 | B21: OpenAI | C21: Proprietary | D21: proprietary | E21: Frontier | F21: undisclosed | I21: 400K | J21: 2025-08-07 | K21: optional | L21: 1 | M21: 0.33 | N21: 3 | O21: T4 | P21: 2025-08 | Q21: Class anchor at time of release; retained so year-on-year comparisons against the 2025 generation remain possible. | R21: Class-based estimate per FRAMEWORK.md §4.5 | S21: legacy
A22: Claude Fable 5.1 | B22: Anthropic | C22: Proprietary | D22: proprietary | E22: Frontier | F22: undisclosed | I22: 1M | J22: 2026-09-01 | K22: always | L22: 1.2 | M22: 0.39 | N22: 3.6 | O22: T4 | P22: 2026-09-01 | Q22: Class anchor for frontier closed-weight serving (§4.5): no parameter disclosure and no published per-request measurement, so the row carries the full T4 band. The ceiling for an API row is T2 and only the provider can lift it (§4.8). Anthropic publishes no per-query or per-token energy, carbon or water figure for any Claude model, so this row cannot rise above T4 without a disclosure. | R22: Anthropic model documentation (platform.claude.com), Sept 2026 | S22: current
A23: Claude Mythos 5.1 | B23: Anthropic | C23: Proprietary | D23: proprietary | E23: Frontier | F23: undisclosed | I23: 1M | J23: 2026-09-01 | K23: always | L23: 1.2 | M23: 0.39 | N23: 3.6 | O23: T4 | P23: 2026-09-01 | Q23: Class anchor for frontier closed-weight serving (§4.5): no parameter disclosure and no published per-request measurement, so the row carries the full T4 band. The ceiling for an API row is T2 and only the provider can lift it (§4.8). Trusted-access only; shares Fable 5.1's specifications. Anthropic publishes no per-query or per-token energy, carbon or water figure for any Claude model, so this row cannot rise above T4 without a disclosure. | R23: Anthropic model documentation (platform.claude.com), Sept 2026 | S23: current
A24: Claude Opus 5 | B24: Anthropic | C24: Proprietary | D24: proprietary | E24: Frontier | F24: undisclosed | I24: 1M | J24: 2026-07-24 | K24: optional | L24: 1.2 | M24: 0.39 | N24: 3.6 | O24: T4 | P24: 2026-07-24 | Q24: Class anchor for frontier closed-weight serving (§4.5): no parameter disclosure and no published per-request measurement, so the row carries the full T4 band. The ceiling for an API row is T2 and only the provider can lift it (§4.8). Anthropic publishes no per-query or per-token energy, carbon or water figure for any Claude model, so this row cannot rise above T4 without a disclosure. | R24: Anthropic model documentation (platform.claude.com), Sept 2026 | S24: current
A25: Claude Sonnet 5 | B25: Anthropic | C25: Proprietary | D25: proprietary | E25: Mid | F25: undisclosed | I25: 1M | J25: 2026-06-30 | K25: optional | L25: 0.3 | M25: 0.09 | N25: 0.9 | O25: T4 | P25: 2026-06-30 | Q25: Class anchor for mid closed-weight serving (§4.5): no parameter disclosure and no published per-request measurement, so the row carries the full T4 band. The ceiling for an API row is T2 and only the provider can lift it (§4.8). Anthropic publishes no per-query or per-token energy, carbon or water figure for any Claude model, so this row cannot rise above T4 without a disclosure. | R25: Anthropic model documentation (platform.claude.com), Sept 2026 | S25: current
A26: Claude Fable 5 | B26: Anthropic | C26: Proprietary | D26: proprietary | E26: Frontier | F26: undisclosed | I26: 1M | J26: 2026-06-09 | K26: always | L26: 1.2 | M26: 0.39 | N26: 3.6 | O26: T4 | P26: 2026-06-09 | Q26: Class anchor for frontier closed-weight serving (§4.5): no parameter disclosure and no published per-request measurement, so the row carries the full T4 band. The ceiling for an API row is T2 and only the provider can lift it (§4.8). Anthropic publishes no per-query or per-token energy, carbon or water figure for any Claude model, so this row cannot rise above T4 without a disclosure. | R26: Anthropic model documentation (platform.claude.com), Sept 2026 | S26: current
A27: Claude Opus 4.8 | B27: Anthropic | C27: Proprietary | D27: proprietary | E27: Frontier | F27: undisclosed | I27: 1M | J27: 2026-05-28 | K27: optional | L27: 1.2 | M27: 0.39 | N27: 3.6 | O27: T4 | P27: 2026-05-28 | Q27: Class anchor for frontier closed-weight serving (§4.5): no parameter disclosure and no published per-request measurement, so the row carries the full T4 band. The ceiling for an API row is T2 and only the provider can lift it (§4.8). Anthropic publishes no per-query or per-token energy, carbon or water figure for any Claude model, so this row cannot rise above T4 without a disclosure. | R27: Anthropic model documentation (platform.claude.com), Sept 2026 | S27: current
A28: Claude Opus 4.6 | B28: Anthropic | C28: Proprietary | D28: proprietary | E28: Frontier | F28: undisclosed | I28: 1M | J28: 2026-02-05 | K28: optional | L28: 1.2 | M28: 0.39 | N28: 3.6 | O28: T4 | P28: 2026-02-05 | Q28: Class anchor for frontier closed-weight serving (§4.5): no parameter disclosure and no published per-request measurement, so the row carries the full T4 band. The ceiling for an API row is T2 and only the provider can lift it (§4.8). Anthropic publishes no per-query or per-token energy, carbon or water figure for any Claude model, so this row cannot rise above T4 without a disclosure. | R28: Anthropic model documentation (platform.claude.com), Sept 2026 | S28: current
... A45: Gemini 2.5 Flash | B45: Google | C45: Proprietary | D45: proprietary | E45: Mid | F45: undisclosed | I45: 1M | J45: 2025-04 | K45: optional | L45: 0.3 | M45: 0.09 | N45: 0.9 | O45: T4 | P45: 2025-04 | Q45: Class anchor for mid closed-weight serving (§4.5): no parameter disclosure and no published per-request measurement, so the row carries the full T4 band. The ceiling for an API row is T2 and only the provider can lift it (§4.8). | R45: Google Gemini model cards (ai.google.dev / DeepMind), 2026 | S45: legacy
A46: Gemma 4 31B | B46: Google | C46: Open | D46: Gemma Terms of Use | E46: Mid | F46: dense | G46: 31 | H46: 31 | I46: 128K | J46: 2026-04-02 | K46: optional | L46: 0.07 | M46: 0.023 | N46: 0.21 | O46: T4 | P46: 2026-04-02 | Q46: T4-physics(A=31): e_out = 2*N_active/(eta*u*3600)*S with eta=1.4e12 FLOPs/J (H100-class BF16), u=0.3, S=1.7. Open weights, so this row can be moved to T1 by metering your own deployment (§4.8). | R46: Google Gemma 4 model cards (April–June 2026) | S46: current
A47: Gemma 4 26B-A4B | B47: Google | C47: Open | D47: Gemma Terms of Use | E47: Mid | F47: MoE | G47: 26 | H47: 3.8 | I47: 128K | J47: 2026-04-02 | K47: optional | L47: 0.0085 | M47: 0.0028 | N47: 0.026 | O47: T4 | P47: 2026-04-02 | Q47: T4-physics(A=3.8): e_out = 2*N_active/(eta*u*3600)*S with eta=1.4e12 FLOPs/J (H100-class BF16), u=0.3, S=1.7. Open weights, so this row can be moved to T1 by metering your own deployment (§4.8). | R47: Google Gemma 4 model cards (April–June 2026) | S47: current
A48: Gemma 4 12B | B48: Google | C48: Open | D48: Gemma Terms of Use | E48: Small | F48: dense | G48: 12 | H48: 12 | I48: 128K | J48: 2026-06-03 | K48: optional | L48: 0.027 | M48: 0.0089 | N48: 0.081 | O48: T4 | P48: 2026-06-03 | Q48: T4-physics(A=12): e_out = 2*N_active/(eta*u*3600)*S with eta=1.4e12 FLOPs/J (H100-class BF16), u=0.3, S=1.7. Open weights, so this row can be moved to T1 by metering your own deployment (§4.8). | R48: Google Gemma 4 model cards (April–June 2026) | S48: current
A49: Gemma 4 E4B | B49: Google | C49: Open | D49: Gemma Terms of Use | E49: Tiny | F49: dense | G49: 4.5 | H49: 4.5 | I49: 128K | J49: 2026-04-02 | K49: optional | L49: 0.01 | M49: 0.0033 | N49: 0.03 | O49: T4 | P49: 2026-04-02 | Q49: T4-physics(A=4.5): e_out = 2*N_active/(eta*u*3600)*S with eta=1.4e12 FLOPs/J (H100-class BF16), u=0.3, S=1.7. Open weights, so this row can be moved to T1 by metering your own deployment (§4.8). Effective-parameter variant for on-device serving. | R49: Google Gemma 4 model cards (April–June 2026) | S49: current
A50: Gemma 4 E2B | B50: Google | C50: Open | D50: Gemma Terms of Use | E50: Tiny | F50: dense | G50: 2.3 | H50: 2.3 | I50: 128K | J50: 2026-04-02 | K50: optional | L50: 0.0052 | M50: 0.0017 | N50: 0.016 | O50: T4 | P50: 2026-04-02 | Q50: T4-physics(A=2.3): e_out = 2*N_active/(eta*u*3600)*S with eta=1.4e12 FLOPs/J (H100-class BF16), u=0.3, S=1.7. Open weights, so this row can be moved to T1 by metering your own deployment (§4.8). | R50: Google Gemma 4 model cards (April–June 2026) | S50: current
A51: Muse Spark 1.3 | B51: Meta | C51: Proprietary | D51: proprietary | E51: Frontier | F51: undisclosed | I51: — | J51: 2026-09-02 | K51: optional | L51: 1.2 | M51: 0.39 | N51: 3.6 | O51: T4 | P51: 2026-09-02 | Q51: Class anchor for frontier closed-weight serving (§4.5): no parameter disclosure and no published per-request measurement, so the row carries the full T4 band. The ceiling for an API row is T2 and only the provider can lift it (§4.8). Meta's frontier line went closed-weight with Muse Spark; no model card energy figures are published for it. | R51: Meta model cards (meta-llama/llama-models, facebookresearch) and product announcements, 2026 | S51: current
A52: Muse Spark 1.2 | B52: Meta | C52: Proprietary | D52: proprietary | E52: Frontier | F52: undisclosed | I52: — | J52: 2026-08-05 | K52: optional | L52: 1.2 | M52: 0.39 | N52: 3.6 | O52: T4 | P52: 2026-08-05 | Q52: Class anchor for frontier closed-weight serving (§4.5): no parameter disclosure and no published per-request measurement, so the row carries the full T4 band. The ceiling for an API row is T2 and only the provider can lift it (§4.8). | R52: Meta model cards (meta-llama/llama-models, facebookresearch) and product announcements, 2026 | S52: current
A53: Muse Glimmer 30B | B53: Meta | C53: Open | D53: Apache-2.0 | E53: Mid | F53: dense | G53: 29.6 | H53: 29.6 | I53: 128K | J53: 2026-08-10 | K53: optional | L53: 0.067 | M53: 0.022 | N53: 0.21 | O53: T4 | P53: 2026-08-10 | Q53: T4-physics(A=29.6): e_out = 2*N_active/(eta*u*3600)*S with eta=1.4e12 FLOPs/J (H100-class BF16), u=0.3, S=1.7. Open weights, so this row can be moved to T1 by metering your own deployment (§4.8). Meta's partial return to open weights after the Muse Spark line went closed. | R53: Meta model cards (meta-llama/llama-models, facebookresearch) and product announcements, 2026 | S53: current
A54: Llama 4 Maverick | B54: Meta | C54: Open | D54: Llama 4 Community | E54: Mid | F54: MoE | G54: 400 | H54: 17 | I54: 1M | J54: 2025-04-05 | K54: no | L54: 0.038 | M54: 0.012 | N54: 0.12 | O54: T4 | P54: 2025-04-05 | Q54: T4-physics(A=17): e_out = 2*N_active/(eta*u*3600)*S with eta=1.4e12 FLOPs/J (H100-class BF16), u=0.3, S=1.7. Open weights, so this row can be moved to T1 by metering your own deployment (§4.8). 17B active of 400B total: energy tracks the 17B, memory tracks the 400B. Conflating the two overstates this row roughly 20-fold. | R54: Meta Llama 4 model card (April 2025) | S54: current
A55: Llama 4 Scout | B55: Meta | C55: Open | D55: Llama 4 Community | E55: Mid | F55: MoE | G55: 109 | H55: 17 | I55: 10M | J55: 2025-04-05 | K55: no | L55: 0.038 | M55: 0.012 | N55: 0.12 | O55: T4 | P55: 2025-04-05 | Q55: T4-physics(A=17): e_out = 2*N_active/(eta*u*3600)*S with eta=1.4e12 FLOPs/J (H100-class BF16), u=0.3, S=1.7. Open weights, so this row can be moved to T1 by metering your own deployment (§4.8). | R55: Meta Llama 4 model card (April 2025) | S55: current
A56: Llama 3.2 3B | B56: Meta | C56: Open | D56: Llama 3.2 Community | E56: Tiny | F56: dense | G56: 3 | H56: 3 | I56: 128K | J56: 2024-10-24 | K56: no | L56: 0.0067 | M56: 0.0022 | N56: 0.021 | O56: T4 | P56: 2024-10-24 | Q56: T4-physics(A=3): e_out = 2*N_active/(eta*u*3600)*S with eta=1.4e12 FLOPs/J (H100-class BF16), u=0.3, S=1.7. Open weights, so this row can be moved to T1 by metering your own deployment (§4.8). | R56: Meta Llama 3.2 model card (Oct 2024) | S56: current
...

Sheet Region Factors
A1: Region | B1: CI location (g CO2e/kWh) | C1: CI low | D1: CI high | E1: EWIF (L/kWh) | F1: EWIF low | G1: EWIF high | H1: Vintage | I1: Source | J1: Notes
A2: Global average | B2: 473 | C2: 425 | D2: 520 | E2: 2 | F2: 1 | G2: 4 | H2: 2024 | I2: Ember Global Electricity Review 2025 (2024 data); EWIF: Li et al. arXiv:2304.03271 + Macknick et al. 2012 | J2: Default when hosting region is unknown
A3: United States | B3: 384 | C3: 350 | D3: 420 | E3: 1.8 | F3: 1 | G3: 3.1 | H3: 2024 | I3: Ember (2024 data); Macknick et al. operational consumption factors | J3: EWIF varies strongly by state (CAISO vs coal states)
A4: EU average | B4: 213 | C4: 190 | D4: 240 | E4: 1.9 | F4: 1 | G4: 3 | H4: 2024 | I4: Ember (2024 data)
A5: France | B5: 40 | C5: 20 | D5: 60 | E5: 2.4 | F5: 1.2 | G5: 3.6 | H5: 2024 | I5: Ember (2024 data) | J5: Nuclear-dominated grid: very low carbon; cooling-tower evaporation raises EWIF
A6: Germany | B6: 344 | C6: 300 | D6: 390 | E6: 1.6 | F6: 0.8 | G6: 2.4 | H6: 2024 | I6: Ember (2024 data)
A7: United Kingdom | B7: 124 | C7: 100 | D7: 150 | E7: 1.4 | F7: 0.7 | G7: 2.1 | H7: 2024 | I7: Ember (2024 data)
A8: Ireland | B8: 280 | C8: 240 | D8: 330 | E8: 1.3 | F8: 0.7 | G8: 2 | H8: 2024 | I8: Ember (2024 data) | J8: Major EU data-center hub
A9: Netherlands | B9: 240 | C9: 200 | D9: 290 | E9: 1.4 | F9: 0.7 | G9: 2.1 | H9: 2024 | I9: Ember (2024 data)
A10: Poland | B10: 620 | C10: 560 | D10: 680 | E10: 1.6 | F10: 0.8 | G10: 2.4 | H10: 2024 | I10: Ember (2024 data) | J10: Highest-carbon grid in the EU
A11: Sweden | B11: 30 | C11: 15 | D11: 45 | E11: 1.2 | F11: 0.6 | G11: 1.8 | H11: 2024 | I11: Ember (2024 data) | J11: Hydro + nuclear
A12: Norway | B12: 30 | C12: 15 | D12: 45 | E12: 1.1 | F12: 0.5 | G12: 1.7 | H12: 2024 | I12: Ember (2024 data) | J12: Hydro-dominated; reservoir-evaporation attribution excluded (contested)
A13: Canada | B13: 170 | C13: 130 | D13: 210 | E13: 1.5 | F13: 0.8 | G13: 2.3 | H13: 2024 | I13: Ember (2024 data) | J13: Hydro-heavy provinces far lower than average
A14: Brazil | B14: 96 | C14: 70 | D14: 130 | E14: 2.5 | F14: 1.2 | G14: 4 | H14: 2024 | I14: Ember (2024 data) | J14: Hydro reservoir evaporation attribution excluded (contested; would raise EWIF several-fold)
A15: China | B15: 534 | C15: 480 | D15: 590 | E15: 2.2 | F15: 1.1 | G15: 3.3 | H15: 2024 | I15: Ember (2024 data)
A16: India | B16: 708 | C16: 640 | D16: 780 | E16: 2.6 | F16: 1.3 | G16: 3.9 | H16: 2024 | I16: Ember (2024 data) | J16: Highest-carbon major grid
A17: Japan | B17: 485 | C17: 440 | D17: 530 | E17: 1.9 | F17: 1 | G17: 2.9 | H17: 2024 | I17: Ember (2024 data)
A18: South Korea | B18: 415 | C18: 370 | D18: 460 | E18: 1.9 | F18: 1 | G18: 2.9 | H18: 2024 | I18: Ember (2024 data)
A19: Singapore | B19: 470 | C19: 420 | D19: 520 | E19: 1.7 | F19: 0.9 | G19: 2.6 | H19: 2024 | I19: Ember (2024 data) | J19: Gas-dominated; major APAC data-center hub
A20: Australia | B20: 549 | C20: 490 | D20: 610 | E20: 2.3 | F20: 1.2 | G20: 3.5 | H20: 2024 | I20: Ember (2024 data)
A21: United Arab Emirates | B21: 430 | C21: 380 | D21: 490 | E21: 1.5 | F21: 0.8 | G21: 2.3 | H21: 2024 | I21: Ember (2024 data) | J21: Gas + growing solar/nuclear
A23: CI = location-based grid carbon intensity (annual average). EWIF = off-site electricity-water intensity factor. Source of truth: data/regions.csv.

Sheet Facility Profiles
A1: Facility profile | B1: PUE | C1: PUE low | D1: PUE high | E1: WUE (L/kWh) | F1: WUE low | G1: WUE high | H1: Source | I1: Notes
A2: Hyperscale (best-in-class) | B2: 1.09 | C2: 1.06 | D2: 1.15 | E2: 0.25 | F2: 0.1 | G2: 0.5 | H2: Google fleet trailing-twelve-month PUE 1.09-1.10; Meta fleet PUE ~1.09 / WUE ~0.20; operator sustainability reports | I2: Leading dedicated AI fleets; air/advanced cooling
A3: Hyperscale cloud (typical) | B3: 1.15 | C3: 1.1 | D3: 1.3 | E3: 1 | F3: 0.4 | G3: 1.8 | H3: Operator sustainability reports: Google fleet WUE ~1.0 L/kWh (2024); Microsoft design PUE 1.12 / WUE 0.49; AWS PUE ~1.15 | I3: Most commercial API serving lands here
A4: Colocation / enterprise (typical) | B4: 1.54 | C4: 1.35 | D4: 1.8 | E4: 1.8 | F4: 0.5 | G4: 2.5 | H4: Uptime Institute Global Data Center Survey 2025: industry average PUE 1.54 (stable six years) | I4: Typical rented rack / mid-size DC
A5: On-premises (legacy) | B5: 1.8 | C5: 1.5 | D5: 2.5 | E5: 1.8 | F5: 0.5 | G5: 3 | H5: Uptime Institute survey distributions (older, smaller facilities) | I5: Small server rooms often exceed PUE 2.0
A6: Unknown (API default) | B6: 1.2 | C6: 1.09 | D6: 1.54 | E6: 1 | F6: 0.2 | G6: 1.8 | H6: Weighted assumption: most commercial LLM serving runs in hyperscale facilities | I6: Default when the facility is unknown
A8: PUE multiplies IT energy into total facility energy. WUE is on-site cooling water per kWh of IT energy. Source of truth: data/facilities.csv.

Sheet Grading
A1: Task class | B1: Code | C1: Default tokens in | D1: Default tokens out | E1: A ≤ (Wh) | F1: B ≤ (Wh) | G1: C ≤ (Wh) | H1: D ≤ (Wh) | I1: E > (Wh) | J1: Description
A2: Light | B2: L | C2: 300 | D2: 80 | E2: 0.1 | F2: 0.3 | G2: 1 | H2: 3 | I2: 3 | J2: Classification, extraction, short chat, autocomplete
A3: Standard | B3: S | C3: 500 | D3: 300 | E3: 0.3 | F3: 1 | G3: 3 | H3: 10 | I3: 10 | J3: General assistant use, summarization, translation
A4: Heavy | B4: H | C4: 2000 | D4: 1000 | E4: 1 | F4: 3 | G4: 10 | H4: 30 | I4: 30 | J4: Long-form generation, RAG over large contexts, code generation
A5: Reasoning/agentic | B5: R | C5: 2000 | D5: 4000 | E5: 3 | F5: 10 | G5: 30 | H5: 100 | I5: 100 | J5: Extended thinking, multi-step agents, deep research (incl. hidden reasoning tokens)
A7: How the bands work (§5.2)
A8: Grades are assigned on CENTRAL-estimate energy per request (full-stack Wh) against FIXED, LOGARITHMIC (~×3 spacing), TASK-CONDITIONED bands.
A9: Fixed absolute bands — rather than percentile ranks — keep grades stable over time and auditable; the ~×3 spacing reflects the order-of-magnitude spreads observed in every benchmark study.
A10: Anchors: provider-disclosed medians (0.24–0.34 Wh/request) anchor grade A/B for class S; reasoning models measured at >30 Wh/request (Jegham et al.; AI Energy Score v2: reasoning ≈ 30× standard) anchor grade E.
A11: Requests are graded WITHIN their task class — comparing a reasoning-agent workload to an autocomplete query is meaningless.
A12: Carbon and water are REPORTED, not graded: they are dominated by region and facility (P3), which model choice cannot fix.
A13: Source of truth: data/grading.csv.

Sheet Mitigation
A1: Rank | B1: Lever | C1: Who controls it | D1: Measured effect | E1: Evidence
A2: 1 | B2: Right-size the model (route each task to the smallest adequate model) | C2: User | D2: 10-70x energy difference between frontier-reasoning and small efficient models on identical prompts | E2: Jegham et al. arXiv:2505.09598 (o3 vs GPT-4.1 nano >70x); AI Energy Score leaderboard spreads
A3: 2 | B3: Cap reasoning/thinking budgets on bounded tasks | C3: User | D3: Reasoning modes average ~30x the energy of standard generation; explicit budgets recover most of it | E3: AI Energy Score v2 (2025); Jegham et al. arXiv:2505.09598 (o3: 21.4 Wh/medium, >33 Wh/long prompt)
A4: 3 | B4: Choose low-carbon hosting regions | C4: User/Provider | D4: Grid carbon intensity spans ~20x across the regions in this table (30-40 gCO2e/kWh hydro/nuclear grids vs 600-750 coal-heavy) | E4: Ember Global Electricity Review (2024 data); data/regions.csv
A5: 4 | B5: Bound output length; prompt and token discipline | C5: User | D5: Per-request energy is approximately linear in output tokens; halving median output roughly halves energy | E5: Physics of autoregressive decoding; Luccioni et al. FAccT 2024
A6: 5 | B6: Cache repeated context and responses | C6: User | D6: Removes prefill recomputation for cached input tokens; the saving equals your measured hit rate applied to the input share of the request (§4.1) | E6: Provider prompt-caching documentation; modelled explicitly in GAIA's cached-input term
A7: 6 | B7: Prefer sparse (mixture-of-experts) serving at equal capability | C7: User/Provider | D7: Per-token energy scales with ACTIVE, not total, parameters: current frontier open-weight models activate 13-104B of 0.3-2.8T, serving at a fraction of a dense model of the same total size | E7: FRAMEWORK.md 4.5 Tier-4 model; published active-parameter counts in data/models.csv
A8: 7 | B8: Batch requests / schedule flexible jobs off-peak | C8: User | D8: Improves serving utilisation; single-digit to low-double-digit % energy; larger carbon effect via diurnal grid variation | E8: Serving-systems literature; grid CI diurnal data
A9: 8 | B9: Meter an open-weight deployment (move the row from T4 to T1) | C9: User | D9: Does not reduce energy: it reduces UNCERTAINTY, from a modelled x/divide-3 band to a measured x/divide-1.15 band — roughly a fourfold narrowing, achievable in an afternoon | E9: GAIA principles P1/P2 and 4.8; CodeCarbon / nvidia-smi plus host power
A10: 9 | B10: Prefer providers that disclose measured footprints | C10: User | D10: Converts Tier-4 guesses into Tier-2 data (halves the interval) and creates market pressure for transparency; only two providers currently publish full-stack or audited figures | E10: Google arXiv:2508.15734; Mistral AI environmental report (2025); GAIA principle P1
A11: 10 | B11: Adopt newer accelerator generations | C11: Provider | D11: ~24% lower embodied carbon per FLOP (B200 vs H100) and higher FLOPs/J in serving; a disclosure ask for vendor management, not a user action | E11: NVIDIA HGX embodied-carbon disclosures
B13: Evidence-ranked levers: every effect size is a measured number with a citation — 'up to' marketing numbers are banned (§6). Provider-side levers (PUE, clean-power procurement, WUE) belong in vendor management as disclosure asks, not user actions. Source of truth: data/mitigation.csv.

Sheet Scenario Compare
B1: Scenario Compare — four options, one workload
B2: Edit the yellow cells. Every column runs the same §4 equations as the Assessment sheet. Column C is the baseline; D–F report their difference against it.
B4: Row | C4: Baseline | D4: Option B | E4: Option C | F4: Option D | G4: Notes
B5: 1 · Model | C5: GPT-6 Astra | D5: Llama 3.2 1B | E5: GPT-6 Astra | F5: Llama 3.2 1B | G5: Dropdown — provenance in 'Model Database'
B6: 2 · Task class | C6: Standard | D6: Standard | E6: Standard | F6: Standard | G6: Sets the grade bands used in row 26
B7: 3 · Tokens in / request | C7: 500 | D7: 500 | E7: 500 | F7: 500
B8: 4 · Tokens out / request | C8: 300 | D8: 300 | E8: 300 | F8: 300
B9: 5 · Requests / month | C9: 10000 | D9: 10000 | E9: 10000 | F9: 10000
B10: 6 · Facility profile | C10: Unknown (API default) | D10: Unknown (API default) | E10: Hyperscale (best-in-class) | F10: Hyperscale (best-in-class)
B11: 7 · Hosting region | C11: Global average | D11: Global average | E11: Sweden | F11: Sweden
B12: 8 · Cached input share (0–1) | C12: 0 | D12: 0 | E12: 0 | F12: 0 | G12: Cache hits skip prefill (§4.1)
B13: 9 · Embodied adder | C13: 0.25 | D13: 0.25 | E13: 0.25 | F13: 0.25 | G13: Default 0.25; range 0.10–0.50 (§4.6)
B15: LOOKED-UP FACTORS (INDEX/MATCH against the data sheets)
B16: e_out — Wh / 1k output tokens | C16: =IFERROR(INDEX('Model Database'!$L$2:$L$136,MATCH(C5,'Model Database'!$A$2:$A$136,0)),"") | D16: =IFERROR(INDEX('Model Database'!$L$2:$L$136,MATCH(D5,'Model Database'!$A$2:$A$136,0)),"") | E16: =IFERROR(INDEX('Model Database'!$L$2:$L$136,MATCH(E5,'Model Database'!$A$2:$A$136,0)),"") | F16: =IFERROR(INDEX('Model Database'!$L$2:$L$136,MATCH(F5,'Model Database'!$A$2:$A$136,0)),"") | G16: models.csv, IT boundary
B17: Data tier | C17: =IFERROR(INDEX('Model Database'!$O$2:$O$136,MATCH(C5,'Model Database'!$A$2:$A$136,0)),"") | D17: =IFERROR(INDEX('Model Database'!$O$2:$O$136,MATCH(D5,'Model Database'!$A$2:$A$136,0)),"") | E17: =IFERROR(INDEX('Model Database'!$O$2:$O$136,MATCH(E5,'Model Database'!$A$2:$A$136,0)),"") | F17: =IFERROR(INDEX('Model Database'!$O$2:$O$136,MATCH(F5,'Model Database'!$A$2:$A$136,0)),"") | G17: T1 measured … T4 modelled
B18: PUE | C18: =IFERROR(INDEX('Facility Profiles'!$B$2:$B$6,MATCH(C10,'Facility Profiles'!$A$2:$A$6,0)),"") | D18: =IFERROR(INDEX('Facility Profiles'!$B$2:$B$6,MATCH(D10,'Facility Profiles'!$A$2:$A$6,0)),"") | E18: =IFERROR(INDEX('Facility Profiles'!$B$2:$B$6,MATCH(E10,'Facility Profiles'!$A$2:$A$6,0)),"") | F18: =IFERROR(INDEX('Facility Profiles'!$B$2:$B$6,MATCH(F10,'Facility Profiles'!$A$2:$A$6,0)),"") | G18: facilities.csv
B19: WUE (L/kWh IT) | C19: =IFERROR(INDEX('Facility Profiles'!$E$2:$E$6,MATCH(C10,'Facility Profiles'!$A$2:$A$6,0)),"") | D19: =IFERROR(INDEX('Facility Profiles'!$E$2:$E$6,MATCH(D10,'Facility Profiles'!$A$2:$A$6,0)),"") | E19: =IFERROR(INDEX('Facility Profiles'!$E$2:$E$6,MATCH(E10,'Facility Profiles'!$A$2:$A$6,0)),"") | F19: =IFERROR(INDEX('Facility Profiles'!$E$2:$E$6,MATCH(F10,'Facility Profiles'!$A$2:$A$6,0)),"") | G19: facilities.csv
B20: Grid CI (g CO2e/kWh) | C20: =IFERROR(INDEX('Region Factors'!$B$2:$B$21,MATCH(C11,'Region Factors'!$A$2:$A$21,0)),"") | D20: =IFERROR(INDEX('Region Factors'!$B$2:$B$21,MATCH(D11,'Region Factors'!$A$2:$A$21,0)),"") | E20: =IFERROR(INDEX('Region Factors'!$B$2:$B$21,MATCH(E11,'Region Factors'!$A$2:$A$21,0)),"") | F20: =IFERROR(INDEX('Region Factors'!$B$2:$B$21,MATCH(F11,'Region Factors'!$A$2:$A$21,0)),"") | G20: regions.csv, location-based
B21: EWIF (L/kWh) | C21: =IFERROR(INDEX('Region Factors'!$E$2:$E$21,MATCH(C11,'Region Factors'!$A$2:$A$21,0)),"") | D21: =IFERROR(INDEX('Region Factors'!$E$2:$E$21,MATCH(D11,'Region Factors'!$A$2:$A$21,0)),"") | E21: =IFERROR(INDEX('Region Factors'!$E$2:$E$21,MATCH(E11,'Region Factors'!$A$2:$A$21,0)),"") | F21: =IFERROR(INDEX('Region Factors'!$E$2:$E$21,MATCH(F11,'Region Factors'!$A$2:$A$21,0)),"") | G21: regions.csv, off-site water
B23: RESULTS — central estimates (§4)
B24: Energy per request (Wh) | C24: =IFERROR(C16*(C8+C7*(1-C12)/10)/1000*C18,"") | D24: =IFERROR(D16*(D8+D7*(1-D12)/10)/1000*D18,"") | E24: =IFERROR(E16*(E8+E7*(1-E12)/10)/1000*E18,"") | F24: =IFERROR(F16*(F8+F7*(1-F12)/10)/1000*F18,"") | G24: E_IT × PUE; E_IT = e_out × (T_out + T_in × (1 − c) / 10) / 1000
B25: Energy per month (kWh) | C25: =IFERROR(C24*C9/1000,"") | D25: =IFERROR(D24*D9/1000,"") | E25: =IFERROR(E24*E9/1000,"") | F25: =IFERROR(F24*F9/1000,"")
B26: Carbon — location-based (kg CO2e/mo) | C26: =IFERROR(C25*C20/1000,"") | D26: =IFERROR(D25*D20/1000,"") | E26: =IFERROR(E25*E20/1000,"") | F26: =IFERROR(F25*F20/1000,"")
B27: Embodied carbon (kg CO2e/mo) | C27: =IFERROR(C26*C13,"") | D27: =IFERROR(D26*D13,"") | E27: =IFERROR(E26*E13,"") | F27: =IFERROR(F26*F13,"")
B28: Water (L/mo) | C28: =IFERROR(C16*(C8+C7*(1-C12)/10)/1000*C9/1000*C19+C25*C21,"") | D28: =IFERROR(D16*(D8+D7*(1-D12)/10)/1000*D9/1000*D19+D25*D21,"") | E28: =IFERROR(E16*(E8+E7*(1-E12)/10)/1000*E9/1000*E19+E25*E21,"") | F28: =IFERROR(F16*(F8+F7*(1-F12)/10)/1000*F9/1000*F19+F25*F21,"") | G28: on-site (IT energy × WUE) + off-site (total energy × EWIF)
B30: Efficiency grade | C30: =IF(OR(C24="",C6=""),"",IF(C24<=INDEX(Grading!$E$2:$E$5,MATCH(C6,Grading!$A$2:$A$5,0)),"A",IF(C24<=INDEX(Grading!$F$2:$F$5,MATCH(C6,Grading!$A$2:$A$5,0)),"B",IF(C24<=INDEX(Grading!$G$2:$G$5,MATCH(C6,Grading!$A$2:$A$5,0)),"C",IF(C24<=INDEX(Grading!$H$2:$H$5,MATCH(C6,Grading!$A$2:$A$5,0)),"D","E"))))) | D30: =IF(OR(D24="",D6=""),"",IF(D24<=INDEX(Grading!$E$2:$E$5,MATCH(D6,Grading!$A$2:$A$5,0)),"A",IF(D24<=INDEX(Grading!$F$2:$F$5,MATCH(D6,Grading!$A$2:$A$5,0)),"B",IF(D24<=INDEX(Grading!$G$2:$G$5,MATCH(D6,Grading!$A$2:$A$5,0)),"C",IF(D24<=INDEX(Grading!$H$2:$H$5,MATCH(D6,Grading!$A$2:$A$5,0)),"D","E"))))) | E30: =IF(OR(E24="",E6=""),"",IF(E24<=INDEX(Grading!$E$2:$E$5,MATCH(E6,Grading!$A$2:$A$5,0)),"A",IF(E24<=INDEX(Grading!$F$2:$F$5,MATCH(E6,Grading!$A$2:$A$5,0)),"B",IF(E24<=INDEX(Grading!$G$2:$G$5,MATCH(E6,Grading!$A$2:$A$5,0)),"C",IF(E24<=INDEX(Grading!$H$2:$H$5,MATCH(E6,Grading!$A$2:$A$5,0)),"D","E"))))) | F30: =IF(OR(F24="",F6=""),"",IF(F24<=INDEX(Grading!$E$2:$E$5,MATCH(F6,Grading!$A$2:$A$5,0)),"A",IF(F24<=INDEX(Grading!$F$2:$F$5,MATCH(F6,Grading!$A$2:$A$5,0)),"B",IF(F24<=INDEX(Grading!$G$2:$G$5,MATCH(F6,Grading!$A$2:$A$5,0)),"C",IF(F24<=INDEX(Grading!$H$2:$H$5,MATCH(F6,Grading!$A$2:$A$5,0)),"D","E"))))) | G30: Central Wh/request vs the task class's bands (§5.2)
B31: Carbon vs baseline | C31: ="baseline" | D31: =IF(OR($C$26="",$C$26=0),"—",IFERROR(D26/$C$26-1,"")) | E31: =IF(OR($C$26="",$C$26=0),"—",IFERROR(E26/$C$26-1,"")) | F31: =IF(OR($C$26="",$C$26=0),"—",IFERROR(F26/$C$26-1,"")) | G31: Negative = lower than column C
B33: Only the differences between columns are meaningful here: the absolute values carry the same tier-driven uncertainty as everywhere else in GAIA (see the Assessment sheet for low/central/high). Comparing a T4 row against a T2 row compares an estimate against a measurement — the tier row above says which is which.

Sheet Usage Log
A1: Usage Log — monthly tracking template
A2: Enter Month, Model, Queries and average tokens; kWh / kg / L are computed with the same §4 engine math, using the CURRENT Assessment facility and region selections (PUE, WUE, CI, EWIF from the Engine sheet). Central estimates only.
A3: Month | B3: Model | C3: Queries | D3: Tokens in avg | E3: Tokens out avg | F3: e_out (Wh/1k out) | G3: Wh / request | H3: Energy (kWh) | I3: Carbon loc. (kg CO2e) | J3: Water (L)
A4: EXAMPLE — overwrite | B4: GPT-4o | C4: 1000 | D4: 500 | E4: 300 | F4: =IF($B4="","",IFERROR(INDEX('Model Database'!$E$2:$E$136,MATCH($B4,'Model Database'!$A$2:$A$136,0)),"")) | G4: =IF(OR($F4="",$D4="",$E4=""),"",$F4*($E4+$D4/10)/1000*Engine!$B$26) | H4: =IF(OR($G4="",$C4=""),"",$G4*$C4/1000) | I4: =IF($H4="","",$H4*Engine!$B$28/1000) | J4: =IF(OR($H4="",$C4=""),"",($F4*($E4+$D4/10)/1000*$C4/1000)*Engine!$B$27+$H4*Engine!$B$29)
F5: =IF($B5="","",IFERROR(INDEX('Model Database'!$E$2:$E$136,MATCH($B5,'Model Database'!$A$2:$A$136,0)),"")) | G5: =IF(OR($F5="",$D5="",$E5=""),"",$F5*($E5+$D5/10)/1000*Engine!$B$26) | H5: =IF(OR($G5="",$C5=""),"",$G5*$C5/1000) | I5: =IF($H5="","",$H5*Engine!$B$28/1000) | J5: =IF(OR($H5="",$C5=""),"",($F5*($E5+$D5/10)/1000*$C5/1000)*Engine!$B$27+$H5*Engine!$B$29)
F6: =IF($B6="","",IFERROR(INDEX('Model Database'!$E$2:$E$136,MATCH($B6,'Model Database'!$A$2:$A$136,0)),"")) | G6: =IF(OR($F6="",$D6="",$E6=""),"",$F6*($E6+$D6/10)/1000*Engine!$B$26) | H6: =IF(OR($G6="",$C6=""),"",$G6*$C6/1000) | I6: =IF($H6="","",$H6*Engine!$B$28/1000) | J6: =IF(OR($H6="",$C6=""),"",($F6*($E6+$D6/10)/1000*$C6/1000)*Engine!$B$27+$H6*Engine!$B$29)
F7: =IF($B7="","",IFERROR(INDEX('Model Database'!$E$2:$E$136,MATCH($B7,'Model Database'!$A$2:$A$136,0)),"")) | G7: =IF(OR($F7="",$D7="",$E7=""),"",$F7*($E7+$D7/10)/1000*Engine!$B$26) | H7: =IF(OR($G7="",$C7=""),"",$G7*$C7/1000) | I7: =IF($H7="","",$H7*Engine!$B$28/1000) | J7: =IF(OR($H7="",$C7=""),"",($F7*($E7+$D7/10)/1000*$C7/1000)*Engine!$B$27+$H7*Engine!$B$29)
F8: =IF($B8="","",IFERROR(INDEX('Model Database'!$E$2:$E$136,MATCH($B8,'Model Database'!$A$2:$A$136,0)),"")) | G8: =IF(OR($F8="",$D8="",$E8=""),"",$F8*($E8+$D8/10)/1000*Engine!$B$26) | H8: =IF(OR($G8="",$C8=""),"",$G8*$C8/1000) | I8: =IF($H8="","",$H8*Engine!$B$28/1000) | J8: =IF(OR($H8="",$C8=""),"",($F8*($E8+$D8/10)/1000*$C8/1000)*Engine!$B$27+$H8*Engine!$B$29)
F9: =IF($B9="","",IFERROR(INDEX('Model Database'!$E$2:$E$136,MATCH($B9,'Model Database'!$A$2:$A$136,0)),"")) | G9: =IF(OR($F9="",$D9="",$E9=""),"",$F9*($E9+$D9/10)/1000*Engine!$B$26) | H9: =IF(OR($G9="",$C9=""),"",$G9*$C9/1000) | I9: =IF($H9="","",$H9*Engine!$B$28/1000) | J9: =IF(OR($H9="",$C9=""),"",($F9*($E9+$D9/10)/1000*$C9/1000)*Engine!$B$27+$H9*Engine!$B$29)
F10: =IF($B10="","",IFERROR(INDEX('Model Database'!$E$2:$E$136,MATCH($B10,'Model Database'!$A$2:$A$136,0)),"")) | G10: =IF(OR($F10="",$D10="",$E10=""),"",$F10*($E10+$D10/10)/1000*Engine!$B$26) | H10: =IF(OR($G10="",$C10=""),"",$G10*$C10/1000) | I10: =IF($H10="","",$H10*Engine!$B$28/1000) | J10: =IF(OR($H10="",$C10=""),"",($F10*($E10+$D10/10)/1000*$C10/1000)*Engine!$B$27+$H10*Engine!$B$29)
F11: =IF($B11="","",IFERROR(INDEX('Model Database'!$E$2:$E$136,MATCH($B11,'Model Database'!$A$2:$A$136,0)),"")) | G11: =IF(OR($F11="",$D11="",$E11=""),"",$F11*($E11+$D11/10)/1000*Engine!$B$26) | H11: =IF(OR($G11="",$C11=""),"",$G11*$C11/1000) | I11: =IF($H11="","",$H11*Engine!$B$28/1000) | J11: =IF(OR($H11="",$C11=""),"",($F11*($E11+$D11/10)/1000*$C11/1000)*Engine!$B$27+$H11*Engine!$B$29)
F12: =IF($B12="","",IFERROR(INDEX('Model Database'!$E$2:$E$136,MATCH($B12,'Model Database'!$A$2:$A$136,0)),"")) | G12: =IF(OR($F12="",$D12="",$E12=""),"",$F12*($E12+$D12/10)/1000*Engine!$B$26) | H12: =IF(OR($G12="",$C12=""),"",$G12*$C12/1000) | I12: =IF($H12="","",$H12*Engine!$B$28/1000) | J12: =IF(OR($H12="",$C12=""),"",($F12*($E12+$D12/10)/1000*$C12/1000)*Engine!$B$27+$H12*Engine!$B$29)
F13: =IF($B13="","",IFERROR(INDEX('Model Database'!$E$2:$E$136,MATCH($B13,'Model Database'!$A$2:$A$136,0)),"")) | G13: =IF(OR($F13="",$D13="",$E13=""),"",$F13*($E13+$D13/10)/1000*Engine!$B$26) | H13: =IF(OR($G13="",$C13=""),"",$G13*$C13/1000) | I13: =IF($H13="","",$H13*Engine!$B$28/1000) | J13: =IF(OR($H13="",$C13=""),"",($F13*($E13+$D13/10)/1000*$C13/1000)*Engine!$B$27+$H13*Engine!$B$29)
F14: =IF($B14="","",IFERROR(INDEX('Model Database'!$E$2:$E$136,MATCH($B14,'Model Database'!$A$2:$A$136,0)),"")) | G14: =IF(OR($F14="",$D14="",$E14=""),"",$F14*($E14+$D14/10)/1000*Engine!$B$26) | H14: =IF(OR($G14="",$C14=""),"",$G14*$C14/1000) | I14: =IF($H14="","",$H14*Engine!$B$28/1000) | J14: =IF(OR($H14="",$C14=""),"",($F14*($E14+$D14/10)/1000*$C14/1000)*Engine!$B$27+$H14*Engine!$B$29)
F15: =IF($B15="","",IFERROR(INDEX('Model Database'!$E$2:$E$136,MATCH($B15,'Model Database'!$A$2:$A$136,0)),"")) | G15: =IF(OR($F15="",$D15="",$E15=""),"",$F15*($E15+$D15/10)/1000*Engine!$B$26) | H15: =IF(OR($G15="",$C15=""),"",$G15*$C15/1000) | I15: =IF($H15="","",$H15*Engine!$B$28/1000) | J15: =IF(OR($H15="",$C15=""),"",($F15*($E15+$D15/10)/1000*$C15/1000)*Engine!$B$27+$H15*Engine!$B$29)
F16: =IF($B16="","",IFERROR(INDEX('Model Database'!$E$2:$E$136,MATCH($B16,'Model Database'!$A$2:$A$136,0)),"")) | G16: =IF(OR($F16="",$D16="",$E16=""),"",$F16*($E16+$D16/10)/1000*Engine!$B$26) | H16: =IF(OR($G16="",$C16=""),"",$G16*$C16/1000) | I16: =IF($H16="","",$H16*Engine!$B$28/1000) | J16: =IF(OR($H16="",$C16=""),"",($F16*($E16+$D16/10)/1000*$C16/1000)*Engine!$B$27+$H16*Engine!$B$29)
A17: TOTAL (12 template rows; example row excluded) | H17: =SUM(H5:H16) | I17: =SUM(I5:I16) | J17: =SUM(J5:J16)

Sheet Methodology & Sources
B1: Methodology & Sources
B2: The §4 equations as implemented in this workbook, the data-quality tier ladder, the system boundary, limitations, and the full source list. Authoritative text: FRAMEWORK.md.
B4: Equations (FRAMEWORK.md §4) — exactly as computed on the Engine sheet
B5: E_IT_request [Wh] = e_out × (T_out + T_in × (1 − c) / 10) / 1000
B6: e_out = model energy per 1000 output tokens at the IT boundary (accelerator + host + idle; the serving-stack multiplier S ≈ 1.7 is ALREADY INCLUDED in the Model Database values). Input tokens cost ≈ 1/10 of output tokens (k = 10, §4.1).
B7: c = cached input share. A prompt-cache hit reuses a computed prefix, so those input tokens are never prefilled again and carry no energy. Output tokens are NEVER cached — generation is autoregressive and is recomputed every time. Use your measured hit rate, not a target; default 0 (§4.1).
B8: E_request [Wh] = E_IT_request × PUE (facility overhead, §4.1)
B9: E_month [kWh] = E_request × Q_month / 1000 (§4.2)
B10: C_op(location) = E_month × CI_location / 1000 [kg CO2e] (§4.3)
B11: C_op(market) = E_month × CI_market / 1000 — only when a market CI is supplied; otherwise 'not provided'. Never blended (P6).
B12: C_embodied = C_op(location) × embodied_adder (default 0.25, range 0.10–0.50, §4.6)
B13: W_month [L] = E_IT_month × WUE_site + E_month × EWIF_region (two-path water, §4.4)
... B16: Data-quality tiers (§4.5) — the provenance ladder
B17: Tier | C17: Basis | D17: Uncertainty band (central ×/÷) | E17: Example
B18: T1 Measured | C18: Direct metering of your deployment (CodeCarbon, nvidia-smi + host power) | D18: 1.15 | E18: Self-hosted Llama with power logging
B19: T2 Disclosed | C19: Provider-published full-stack measurement with stated boundary | D19: 1.5 | E19: Google Gemini 0.24 Wh/median prompt; Mistral Large 2 LCA
B20: T3 Benchmarked | C20: Independent standardized benchmark (GPU-only, needs S) | D20: 2 | E20: AI Energy Score; Jegham et al. API benchmarks
B21: T4 Modelled | C21: Parameter-count physics model on ACTIVE parameters (FLOPs → J via hardware efficiency) | D21: 3 | E21: EcoLogits-style estimate for an undisclosed model
B22: The tier band is the default MINIMUM width: low = central ÷ band, high = central × band; a model row may carry wider bounds where sources disagree (documented in its basis column) — the stored wh_low/wh_high are authoritative. Downstream results scale by the energy bounds (energy-dominated); factor uncertainty (CI, PUE, WUE, EWIF) adds beyond the displayed band and is disclosed in the factor sheets.
B24: System boundary (§2)
B25: In scope: accelerator energy for inference; host CPU/DRAM/storage/idle (serving-stack multiplier); data-center overhead (PUE); grid carbon (location- and market-based CI); on-site cooling water + off-site electricity-generation water; embodied emissions of serving hardware (amortized adder); amortized training footprint (optional, OFF by default — it belongs to the provider's inventory under GHG Protocol logic).
B26: Out of scope (documented per ISO 14044 cut-off rules): end-user devices, network transmission (typically <5% of a generative-AI request's footprint), data-center construction, end-of-life — a truncation that understates the true total by an estimated 5–15%.
B28: Known limitations (§10, stated per P2)
